Workbook

Sheet Dashboard
A1: Chipanga Water + Food Project — Summary
A2: Layered model: well + solar → tanks → drip-irrigated school + women's gardens
A3: Edit assumptions on the 'Inputs' tab — every number below recalculates.
A5: Water supply
A6: Metric | B6: Value | C6: Unit | D6: Source / note
A7: Pump rated output | B7: =Inputs!B14 -> 5000 | C7: L/hr
A8: Avg daily supply (across year) | B8: =Well_Solar!F17 -> 27320.417 | C8: L/day
A9: Annual water available | B9: =Well_Solar!G17 -> 9977555 | C9: L/year
A10: Total system storage | B10: =Tank_Sizing!B15 -> 24000 | C10: L
A11: Garden buffer (tanks if pump down) | B11: =Tank_Sizing!B17 -> 0.70333538 | C11: days
A13: Garden area
A14: Metric | B14: Value | C14: Unit | D14: Source / note
A15: Women's garden | B15: =Tank_Sizing!B5 -> 3035.145 | C15: m² | D15: 1 acre ÷ 10 plots
A16: School garden | B16: =Tank_Sizing!B6 -> 3035.145 | C16: m²
A17: Total productive area | B17: =Tank_Sizing!B7 -> 6070.29 | C17: m²
A19: Food output (annual)
A20: Metric | B20: Value | C20: Unit | D20: Source / note
A21: Total food produced | B21: =Food_Yield!H8 -> 59640.599 | C21: kg/year
A22: of which leafy greens | B22: =Food_Yield!H5 -> 45527.175 | C22: kg/year
A23: of which tomato | B23: =Food_Yield!H6 -> 10926.522 | C23: kg/year
A24: of which okra | B24: =Food_Yield!H7 -> 3186.9023 | C24: kg/year
A25: People fed year-round (vegetables) | B25: =Food_Yield!B13 -> 408.49726 | C25: people | D25: @ 0.4 kg/person/day FAO recommendation
A27: Efficiency wins (drip + mulch + compost)
A28: Metric | B28: Value | C28: Unit | D28: Note
A29: Drip vs hand-watering savings | B29: =Irrigation!B17 -> 0.38888889
A30: Mulch + compost savings | B30: =Irrigation!B18 -> 0.3625
A31: Combined (drip + mulch + compost) vs hand | B31: =Irrigation!B19 -> 0.61041667

Sheet Inputs
A1: Chipanga Water + Food Model — Inputs
A2: Edit blue values to run scenarios. Yellow = key assumptions to verify with field data.
A4: Project basics
A5: Item | B5: Value | C5: Unit | D5: Notes
A6: Village | B6: Chipanga
A7: Region | B7: Dodoma Region, Bahi District (~6°S, ~1100 m elev.)
A8: Climate zone | B8: Hot semi-arid (Köppen BSh) — long dry season May–Oct
A10: Well & pump
A11: Item | B11: Value | C11: Unit | D11: Notes
A12: Well diameter | B12: 6 | C12: ft
A13: Well depth | B13: 180 | C13: m
A14: Pump max sustainable output | B14: 5000 | C14: L/hr
A15: Sustainable yield safety factor | B15: 0.85 | C15: fraction
A17: Solar
A18: Item | B18: Value | C18: Unit | D18: Notes
A19: Number of solar panels | B19: 12 | C19: panels
A20: Useful sun hours (peak month) | B20: 7 | C20: hr/day
A22: Tanks
A23: Item | B23: Value | C23: Unit | D23: Notes
A24: School tank | B24: 4000 | C24: L
A25: Garden tank A (women's) | B25: 10000 | C25: L
A26: Garden tank B (school garden) | B26: 10000 | C26: L
A28: Plot areas
A29: Item | B29: Value | C29: Unit | D29: Notes
A30: Women's garden total area | B30: 0.75 | C30: acres | D30: 55m × 55m, Charlie 2026-05-10. Subdivided into 10 plots in field.
A31: Number of women's plots | B31: 10 | C31: plots
A32: School garden area | B32: 0.75 | C32: acres | D32: 55m × 55m, Charlie 2026-05-10.
A33: Acres → m² conversion | B33: 4046.86 | C33: m²/acre
A35: Reference ET₀ by month (mm/day)
A36: Month | B36: ET₀ mm/day | C36: Solar factor | D36: Notes
A37: Jan | B37: 5.4 | C37: 0.8 | D37: ET₀ from FAO-56 climate zone proxy; refine with CLIMWAT/local data
A38: Feb | B38: 5.4 | C38: 0.82
A39: Mar | B39: 5.2 | C39: 0.85
A40: Apr | B40: 4.6 | C40: 0.88
A41: May | B41: 4.2 | C41: 0.95
A42: Jun | B42: 4 | C42: 1
A43: Jul | B43: 4.2 | C43: 1
A44: Aug | B44: 4.8 | C44: 1
A45: Sep | B45: 5.6 | C45: 1
A46: Oct | B46: 6.2 | C46: 1
...

Sheet Well_Solar
A1: Monthly water supply potential
A2: Pump-rated × safety factor × useful sun hours × solar factor → daily/monthly L
A4: Month | B4: Days | C4: ET₀ mm/d | D4: Solar factor | E4: Useful sun (hr/day) | F4: Daily supply (L) | G4: Monthly supply (L)
A5: Jan | B5: 31 | C5: =Inputs!B37 -> 5.4 | D5: =Inputs!C37 -> 0.8 | E5: =Inputs!B20*D5 -> 5.6 | F5: =Inputs!B14*Inputs!B15*E5 -> 23800 | G5: =B5*F5 -> 737800
A6: Feb | B6: 28 | C6: =Inputs!B38 -> 5.4 | D6: =Inputs!C38 -> 0.82 | E6: =Inputs!B20*D6 -> 5.74 | F6: =Inputs!B14*Inputs!B15*E6 -> 24395 | G6: =B6*F6 -> 683060
A7: Mar | B7: 31 | C7: =Inputs!B39 -> 5.2 | D7: =Inputs!C39 -> 0.85 | E7: =Inputs!B20*D7 -> 5.95 | F7: =Inputs!B14*Inputs!B15*E7 -> 25287.5 | G7: =B7*F7 -> 783912.5
A8: Apr | B8: 30 | C8: =Inputs!B40 -> 4.6 | D8: =Inputs!C40 -> 0.88 | E8: =Inputs!B20*D8 -> 6.16 | F8: =Inputs!B14*Inputs!B15*E8 -> 26180 | G8: =B8*F8 -> 785400
A9: May | B9: 31 | C9: =Inputs!B41 -> 4.2 | D9: =Inputs!C41 -> 0.95 | E9: =Inputs!B20*D9 -> 6.65 | F9: =Inputs!B14*Inputs!B15*E9 -> 28262.5 | G9: =B9*F9 -> 876137.5
A10: Jun | B10: 30 | C10: =Inputs!B42 -> 4 | D10: =Inputs!C42 -> 1 | E10: =Inputs!B20*D10 -> 7 | F10: =Inputs!B14*Inputs!B15*E10 -> 29750 | G10: =B10*F10 -> 892500
A11: Jul | B11: 31 | C11: =Inputs!B43 -> 4.2 | D11: =Inputs!C43 -> 1 | E11: =Inputs!B20*D11 -> 7 | F11: =Inputs!B14*Inputs!B15*E11 -> 29750 | G11: =B11*F11 -> 922250
A12: Aug | B12: 31 | C12: =Inputs!B44 -> 4.8 | D12: =Inputs!C44 -> 1 | E12: =Inputs!B20*D12 -> 7 | F12: =Inputs!B14*Inputs!B15*E12 -> 29750 | G12: =B12*F12 -> 922250
A13: Sep | B13: 30 | C13: =Inputs!B45 -> 5.6 | D13: =Inputs!C45 -> 1 | E13: =Inputs!B20*D13 -> 7 | F13: =Inputs!B14*Inputs!B15*E13 -> 29750 | G13: =B13*F13 -> 892500
A14: Oct | B14: 31 | C14: =Inputs!B46 -> 6.2 | D14: =Inputs!C46 -> 1 | E14: =Inputs!B20*D14 -> 7 | F14: =Inputs!B14*Inputs!B15*E14 -> 29750 | G14: =B14*F14 -> 922250
A15: Nov | B15: 30 | C15: =Inputs!B47 -> 6 | D15: =Inputs!C47 -> 0.9 | E15: =Inputs!B20*D15 -> 6.3 | F15: =Inputs!B14*Inputs!B15*E15 -> 26775 | G15: =B15*F15 -> 803250
A16: Dec | B16: 31 | C16: =Inputs!B48 -> 5.6 | D16: =Inputs!C48 -> 0.82 | E16: =Inputs!B20*D16 -> 5.74 | F16: =Inputs!B14*Inputs!B15*E16 -> 24395 | G16: =B16*F16 -> 756245
A17: Annual total | F17: =AVERAGE(F5:F16) -> 27320.417 | G17: =SUM(G5:G16) -> 9977555

Sheet ET_Demand
A1: Crop water demand by month (net, mm/day → L/m²/day)
A2: ETc = Kc × ET₀. Net demand assumes irrigation supplies the full ETc with no rainfall (dry season focus).
A4: Month | B4: ET₀ mm/d | C4: Leafy ETc mm/d | D4: Tomato ETc mm/d | E4: Okra ETc mm/d | F4: Leafy L/m²/d | G4: Tomato L/m²/d | H4: Okra L/m²/d
A5: Jan | B5: =Inputs!B37 -> 5.4 | C5: =Inputs!B52*B5 -> 5.4 | D5: =Inputs!B53*B5 -> 6.21 | E5: =Inputs!B54*B5 -> 5.67 | F5: =C5 -> 5.4 | G5: =D5 -> 6.21 | H5: =E5 -> 5.67
A6: Feb | B6: =Inputs!B38 -> 5.4 | C6: =Inputs!B52*B6 -> 5.4 | D6: =Inputs!B53*B6 -> 6.21 | E6: =Inputs!B54*B6 -> 5.67 | F6: =C6 -> 5.4 | G6: =D6 -> 6.21 | H6: =E6 -> 5.67
A7: Mar | B7: =Inputs!B39 -> 5.2 | C7: =Inputs!B52*B7 -> 5.2 | D7: =Inputs!B53*B7 -> 5.98 | E7: =Inputs!B54*B7 -> 5.46 | F7: =C7 -> 5.2 | G7: =D7 -> 5.98 | H7: =E7 -> 5.46
A8: Apr | B8: =Inputs!B40 -> 4.6 | C8: =Inputs!B52*B8 -> 4.6 | D8: =Inputs!B53*B8 -> 5.29 | E8: =Inputs!B54*B8 -> 4.83 | F8: =C8 -> 4.6 | G8: =D8 -> 5.29 | H8: =E8 -> 4.83
A9: May | B9: =Inputs!B41 -> 4.2 | C9: =Inputs!B52*B9 -> 4.2 | D9: =Inputs!B53*B9 -> 4.83 | E9: =Inputs!B54*B9 -> 4.41 | F9: =C9 -> 4.2 | G9: =D9 -> 4.83 | H9: =E9 -> 4.41
A10: Jun | B10: =Inputs!B42 -> 4 | C10: =Inputs!B52*B10 -> 4 | D10: =Inputs!B53*B10 -> 4.6 | E10: =Inputs!B54*B10 -> 4.2 | F10: =C10 -> 4 | G10: =D10 -> 4.6 | H10: =E10 -> 4.2
A11: Jul | B11: =Inputs!B43 -> 4.2 | C11: =Inputs!B52*B11 -> 4.2 | D11: =Inputs!B53*B11 -> 4.83 | E11: =Inputs!B54*B11 -> 4.41 | F11: =C11 -> 4.2 | G11: =D11 -> 4.83 | H11: =E11 -> 4.41
A12: Aug | B12: =Inputs!B44 -> 4.8 | C12: =Inputs!B52*B12 -> 4.8 | D12: =Inputs!B53*B12 -> 5.52 | E12: =Inputs!B54*B12 -> 5.04 | F12: =C12 -> 4.8 | G12: =D12 -> 5.52 | H12: =E12 -> 5.04
A13: Sep | B13: =Inputs!B45 -> 5.6 | C13: =Inputs!B52*B13 -> 5.6 | D13: =Inputs!B53*B13 -> 6.44 | E13: =Inputs!B54*B13 -> 5.88 | F13: =C13 -> 5.6 | G13: =D13 -> 6.44 | H13: =E13 -> 5.88
A14: Oct | B14: =Inputs!B46 -> 6.2 | C14: =Inputs!B52*B14 -> 6.2 | D14: =Inputs!B53*B14 -> 7.13 | E14: =Inputs!B54*B14 -> 6.51 | F14: =C14 -> 6.2 | G14: =D14 -> 7.13 | H14: =E14 -> 6.51
A15: Nov | B15: =Inputs!B47 -> 6 | C15: =Inputs!B52*B15 -> 6 | D15: =Inputs!B53*B15 -> 6.9 | E15: =Inputs!B54*B15 -> 6.3 | F15: =C15 -> 6 | G15: =D15 -> 6.9 | H15: =E15 -> 6.3
A16: Dec | B16: =Inputs!B48 -> 5.6 | C16: =Inputs!B52*B16 -> 5.6 | D16: =Inputs!B53*B16 -> 6.44 | E16: =Inputs!B54*B16 -> 5.88 | F16: =C16 -> 5.6 | G16: =D16 -> 6.44 | H16: =E16 -> 5.88
A17: Annual avg | B17: =AVERAGE(B5:B16) -> 5.1 | C17: =AVERAGE(C5:C16) -> 5.1 | D17: =AVERAGE(D5:D16) -> 5.865 | E17: =AVERAGE(E5:E16) -> 5.355 | F17: =AVERAGE(F5:F16) -> 5.1 | G17: =AVERAGE(G5:G16) -> 5.865 | H17: =AVERAGE(H5:H16) -> 5.355

Sheet Irrigation
A1: Irrigation method comparison & savings
A2: Net crop demand (ETc) ÷ method efficiency = gross water to apply. Mulch & compost reduce required gross.
A4: A. Combined savings factor
A5: Scenario | B5: Mulch? | C5: Compost? | D5: Net demand multiplier
A6: Baseline (no mulch, no compost) | B6: No | C6: No | D6: =1 -> 1
A7: Mulch only | B7: Yes | C7: No | D7: =(1-Inputs!B73) -> 0.75
A8: Compost only | B8: No | C8: Yes | D8: =(1-Inputs!B74) -> 0.85
A9: Mulch + compost (recommended) | B9: Yes | C9: Yes | D9: =(1-Inputs!B73)*(1-Inputs!B74) -> 0.6375
A11: B. Gross water (L/m²/day, peak month Oct, all crops weighted)
A12: Reference: peak ET₀ in Oct → uses average crop Kc weighted across leafy/tom/okra (assume equal 1/3 split for this comparison)
A13: Method | B13: Net L/m²/d (peak) | C13: Hand (eff) | D13: Drip (eff) | E13: Hand gross L/m²/d | F13: Drip gross L/m²/d
A14: Baseline | B14: =Inputs!B46*AVERAGE(Inputs!B52,Inputs!B53,Inputs!B54) -> 6.6133333 | C14: =Inputs!B71 -> 0.55 | D14: =Inputs!B72 -> 0.9 | E14: =B14/C14 -> 12.024242 | F14: =B14/D14 -> 7.3481481
A15: With mulch + compost | B15: =B14*(1-Inputs!B73)*(1-Inputs!B74) -> 4.216 | C15: =Inputs!B71 -> 0.55 | D15: =Inputs!B72 -> 0.9 | E15: =B15/C15 -> 7.6654545 | F15: =B15/D15 -> 4.6844444
A17: Drip vs hand water savings (peak) | B17: =1-F14/E14 -> 0.38888889
A18: Mulch+compost vs baseline savings | B18: =1-B15/B14 -> 0.3625
A19: Combined drip + mulch + compost vs hand baseline | B19: =1-F15/E14 -> 0.61041667

Sheet Tank_Sizing
A1: Tank sizing & buffer analysis
A2: Compares total tank storage to peak-month daily garden demand → buffer days if pump down.
A4: Item | B4: Value | C4: Unit | D4: Notes
A5: Women's garden area | B5: =Inputs!B30*Inputs!B33 -> 3035.145 | C5: m²
A6: School garden area | B6: =Inputs!B32*Inputs!B33 -> 3035.145 | C6: m²
A7: Total garden area | B7: =B5+B6 -> 6070.29 | C7: m²
A9: Peak-month net demand (Oct, weighted Kc) | B9: =Inputs!B46*AVERAGE(Inputs!B52,Inputs!B53,Inputs!B54) -> 6.6133333 | C9: L/m²/day
A10: Peak gross demand (drip + mulch + compost) | B10: =B9*(1-Inputs!B73)*(1-Inputs!B74)/Inputs!B72 -> 4.6844444 | C10: L/m²/day
A11: Peak total daily garden demand | B11: =B7*B10 -> 28435.936 | C11: L/day
A13: Garden tank storage (A + B) | B13: =Inputs!B25+Inputs!B26 -> 20000 | C13: L
A14: School tank storage | B14: =Inputs!B24 -> 4000 | C14: L
A15: Total system storage | B15: =B13+B14 -> 24000 | C15: L
A17: Buffer (garden tanks ÷ peak demand) | B17: =IFERROR(B13/B11,0) -> 0.70333538 | C17: days
A18: Daily supply (peak month Oct) | B18: =Well_Solar!F14 -> 29750 | C18: L/day
A19: Supply ÷ demand ratio (peak) | B19: =IFERROR(B18/B11,0) -> 1.0462114 | C19: ratio | D19: ≥1.0 = pump can keep up; <1.0 = drawing down storage
A21: Monthly supply vs demand
A22: Month | B22: Supply L/day | C22: Demand L/day | D22: Surplus L/day | E22: Surplus %
A23: Jan | B23: =Well_Solar!F5 -> 23800 | C23: =B7*Inputs!B37*AVERAGE(Inputs!B52,Inputs!B53,Inputs!B54)*(1-Inputs!B73)*(1-Inputs!B74)/Inputs!B72 -> 24766.783 | D23: =B23-C23 -> -966.7832 | E23: =IFERROR(D23/C23,0) -> -0.039035477
A24: Feb | B24: =Well_Solar!F6 -> 24395 | C24: =B7*Inputs!B38*AVERAGE(Inputs!B52,Inputs!B53,Inputs!B54)*(1-Inputs!B73)*(1-Inputs!B74)/Inputs!B72 -> 24766.783 | D24: =B24-C24 -> -371.7832 | E24: =IFERROR(D24/C24,0) -> -0.015011364
A25: Mar | B25: =Well_Solar!F7 -> 25287.5 | C25: =B7*Inputs!B39*AVERAGE(Inputs!B52,Inputs!B53,Inputs!B54)*(1-Inputs!B73)*(1-Inputs!B74)/Inputs!B72 -> 23849.495 | D25: =B25-C25 -> 1438.0051 | E25: =IFERROR(D25/C25,0) -> 0.06029499
A26: Apr | B26: =Well_Solar!F8 -> 26180 | C26: =B7*Inputs!B40*AVERAGE(Inputs!B52,Inputs!B53,Inputs!B54)*(1-Inputs!B73)*(1-Inputs!B74)/Inputs!B72 -> 21097.63 | D26: =B26-C26 -> 5082.3699 | E26: =IFERROR(D26/C26,0) -> 0.24089767
A27: May | B27: =Well_Solar!F9 -> 28262.5 | C27: =B7*Inputs!B41*AVERAGE(Inputs!B52,Inputs!B53,Inputs!B54)*(1-Inputs!B73)*(1-Inputs!B74)/Inputs!B72 -> 19263.054 | D27: =B27-C27 -> 8999.4464 | E27: =IFERROR(D27/C27,0) -> 0.46718691
A28: Jun | B28: =Well_Solar!F10 -> 29750 | C28: =B7*Inputs!B42*AVERAGE(Inputs!B52,Inputs!B53,Inputs!B54)*(1-Inputs!B73)*(1-Inputs!B74)/Inputs!B72 -> 18345.765 | D28: =B28-C28 -> 11404.235 | E28: =IFERROR(D28/C28,0) -> 0.62162763
A29: Jul | B29: =Well_Solar!F11 -> 29750 | C29: =B7*Inputs!B43*AVERAGE(Inputs!B52,Inputs!B53,Inputs!B54)*(1-Inputs!B73)*(1-Inputs!B74)/Inputs!B72 -> 19263.054 | D29: =B29-C29 -> 10486.946 | E29: =IFERROR(D29/C29,0) -> 0.54440727
A30: Aug | B30: =Well_Solar!F12 -> 29750 | C30: =B7*Inputs!B44*AVERAGE(Inputs!B52,Inputs!B53,Inputs!B54)*(1-Inputs!B73)*(1-Inputs!B74)/Inputs!B72 -> 22014.918 | D30: =B30-C30 -> 7735.0816 | E30: =IFERROR(D30/C30,0) -> 0.35135636
A31: Sep | B31: =Well_Solar!F13 -> 29750 | C31: =B7*Inputs!B45*AVERAGE(Inputs!B52,Inputs!B53,Inputs!B54)*(1-Inputs!B73)*(1-Inputs!B74)/Inputs!B72 -> 25684.071 | D31: =B31-C31 -> 4065.9285 | E31: =IFERROR(D31/C31,0) -> 0.15830545
A32: Oct | B32: =Well_Solar!F14 -> 29750 | C32: =B7*Inputs!B46*AVERAGE(Inputs!B52,Inputs!B53,Inputs!B54)*(1-Inputs!B73)*(1-Inputs!B74)/Inputs!B72 -> 28435.936 | D32: =B32-C32 -> 1314.0637 | E32: =IFERROR(D32/C32,0) -> 0.046211376
A33: Nov | B33: =Well_Solar!F15 -> 26775 | C33: =B7*Inputs!B47*AVERAGE(Inputs!B52,Inputs!B53,Inputs!B54)*(1-Inputs!B73)*(1-Inputs!B74)/Inputs!B72 -> 27518.648 | D33: =B33-C33 -> -743.648 | E33: =IFERROR(D33/C33,0) -> -0.027023421
A34: Dec | B34: =Well_Solar!F16 -> 24395 | C34: =B7*Inputs!B48*AVERAGE(Inputs!B52,Inputs!B53,Inputs!B54)*(1-Inputs!B73)*(1-Inputs!B74)/Inputs!B72 -> 25684.071 | D34: =B34-C34 -> -1289.0715 | E34: =IFERROR(D34/C34,0) -> -0.05018953

Sheet Food_Yield
A1: Annual food production estimate
A2: Yield = area × allocation% × yield/m²/cycle × cycles/year. Assumes adequate water (verify on Tank_Sizing).
A4: Crop | B4: Women's m² | C4: School m² | D4: Yield kg/m²/cycle | E4: Cycles/yr | F4: Women's kg/yr | G4: School kg/yr | H4: Total kg/yr
A5: Leafy greens (sukuma/amaranth) | B5: =Inputs!B30*Inputs!B33*Inputs!B64 -> 1517.5725 | C5: =Inputs!B32*Inputs!B33*Inputs!C64 -> 2124.6015 | D5: =Inputs!D52 -> 2.5 | E5: =Inputs!B58 -> 5 | F5: =B5*D5*E5 -> 18969.656 | G5: =C5*D5*E5 -> 26557.519 | H5: =F5+G5 -> 45527.175
A6: Tomato | B6: =Inputs!B30*Inputs!B33*Inputs!B65 -> 758.78625 | C6: =Inputs!B32*Inputs!B33*Inputs!C65 -> 607.029 | D6: =Inputs!D53 -> 4 | E6: =Inputs!B59 -> 2 | F6: =B6*D6*E6 -> 6070.29 | G6: =C6*D6*E6 -> 4856.232 | H6: =F6+G6 -> 10926.522
A7: Okra | B7: =Inputs!B30*Inputs!B33*Inputs!B66 -> 758.78625 | C7: =Inputs!B32*Inputs!B33*Inputs!C66 -> 303.5145 | D7: =Inputs!D54 -> 1.5 | E7: =Inputs!B60 -> 2 | F7: =B7*D7*E7 -> 2276.3587 | G7: =C7*D7*E7 -> 910.5435 | H7: =F7+G7 -> 3186.9023
A8: Total kg/year | B8: =SUM(B5:B7) -> 3035.145 | C8: =SUM(C5:C7) -> 3035.145 | F8: =SUM(F5:F7) -> 27316.305 | G8: =SUM(G5:G7) -> 32324.294 | H8: =SUM(H5:H7) -> 59640.599
A10: Servings & people-fed estimates
A11: Vegetable serving (FAO recommendation) | B11: 0.4 | C11: kg/person/day
A12: Person-days of vegetables / year | B12: =H8/B11 -> 149101.5
A13: People fed year-round (365 days) | B13: =B12/365 -> 408.49726

Sheet Sources
A1: Sources & assumptions
A2: Refine these as field data arrives. Anything in yellow on Inputs is high-leverage.
A4: Reference ET₀ | B4: FAO Irrigation & Drainage Paper 56 — climate zone proxy. Refine with CLIMWAT 2.0 / NASA POWER once village coordinates available.
A5: Crop coefficients (Kc) | B5: FAO-56 Table 12 — leafy greens (lettuce/cabbage proxy), tomato, okra mid-season values.
A6: Drip irrigation efficiency | B6: FAO range 85–95% for well-managed drip. Defaulted to 90%.
A7: Hand-watering efficiency | B7: FAO smallholder range 40–60% (bucket/can application). Defaulted to 55%.
A8: Mulch water savings | B8: Multiple ICRISAT / FAO field studies, 20–40% reduction in soil evaporation. Defaulted to 25%.
A9: Compost retention bonus | B9: Soil organic matter studies show 10–20% improvement in available water capacity. Defaulted to 15%.
A10: Crop yields (smallholder) | B10: Tanzania MoA + ICRISAT smallholder dryland-irrigated benchmarks. Adjustable per Inputs.
A11: Pump output | B11: Per Charlie (Peace Corps): 5,000 L/hr max sustainable from 180 m well.
A12: Solar useful sun hours | B12: Equator-region peak ~7 hr/day useful (NASA POWER). Refine for Tanzania with local irradiance data.
A13: Vegetable serving size | B13: FAO/WHO recommendation 400 g/person/day fruit + vegetables.
